<?xml version="1.0" encoding="utf-8"?>
<!-- This URDF was automatically created by SolidWorks to URDF Exporter! Originally created by Stephen Brawner (brawner@gmail.com) 
     Commit Version: 1.5.1-0-g916b5db  Build Version: 1.5.7152.31018
     For more information, please see http://wiki.ros.org/sw_urdf_exporter -->
<robot
  name="gripper_demo2">
  <link
    name="base_link">
    <inertial>
      <origin
        xyz="0.019 0.040372 0.052951"
        rpy="0 0 0" />
      <mass
        value="0.78663" />
      <inertia
        ixx="0.0011861"
        ixy="8.1251E-21"
        ixz="9.4527E-21"
        iyy="0.00092077"
        iyz="4.1807E-05"
        izz="0.00046469" />
    </inertial>
    <visual>
      <origin
        xyz="0 0 0"
        rpy="0 0 0" />
      <geometry>
        <mesh
          filename="package://gripper_demo2/meshes/base_link.STL" />
      </geometry>
      <material
        name="">
        <color
          rgba="0.89804 0.91765 0.92941 1" />
      </material>
    </visual>
    <collision>
      <origin
        xyz="0 0 0"
        rpy="0 0 0" />
      <geometry>
        <mesh
          filename="package://gripper_demo2/meshes/base_link.STL" />
      </geometry>
    </collision>
  </link>
  <link
    name="finger1_link">
    <inertial>
      <origin
        xyz="0.019 0.051584 0.18424"
        rpy="0 0 0" />
      <mass
        value="0.0167" />
      <inertia
        ixx="2.845E-05"
        ixy="1.4925E-13"
        ixz="-1.4676E-12"
        iyy="2.8128E-05"
        iyz="-1.5257E-06"
        izz="1.7856E-06" />
    </inertial>
    <visual>
      <origin
        xyz="0 0 0"
        rpy="0 0 0" />
      <geometry>
        <mesh
          filename="package://gripper_demo2/meshes/finger1_link.STL" />
      </geometry>
      <material
        name="">
        <color
          rgba="1 1 1 1" />
      </material>
    </visual>
    <collision>
      <origin
        xyz="0 0 0"
        rpy="0 0 0" />
      <geometry>
        <mesh
          filename="package://gripper_demo2/meshes/finger1_link.STL" />
      </geometry>
    </collision>
  </link>
  <joint
    name="joint_1"
    type="continuous">
    <origin
      xyz="0 0 0"
      rpy="0 0 0" />
    <parent
      link="base_link" />
    <child
      link="finger1_link" />
    <axis
      xyz="1 0 0" />
  </joint>
  <link
    name="finger2_link">
    <inertial>
      <origin
        xyz="0.019 0.0093241 0.17673"
        rpy="0 0 0" />
      <mass
        value="0.016641" />
      <inertia
        ixx="3.3375E-05"
        ixy="6.5598E-11"
        ixz="-2.1921E-10"
        iyy="3.084E-05"
        iyz="7.2184E-06"
        izz="3.1595E-06" />
    </inertial>
    <visual>
      <origin
        xyz="0 0 0"
        rpy="0 0 0" />
      <geometry>
        <mesh
          filename="package://gripper_demo2/meshes/finger2_link.STL" />
      </geometry>
      <material
        name="">
        <color
          rgba="1 1 1 1" />
      </material>
    </visual>
    <collision>
      <origin
        xyz="0 0 0"
        rpy="0 0 0" />
      <geometry>
        <mesh
          filename="package://gripper_demo2/meshes/finger2_link.STL" />
      </geometry>
    </collision>
  </link>
  <joint
    name="joint_2"
    type="continuous">
    <origin
      xyz="0 0 0"
      rpy="0 0 0" />
    <parent
      link="base_link" />
    <child
      link="finger2_link" />
    <axis
      xyz="1 0 0" />
  </joint>
</robot>